from django.contrib.auth.forms import UserCreationForm, AuthenticationForm
from django.contrib.auth.models import User
from django import forms
from django.core.exceptions import ValidationError


class LoginUserForm(AuthenticationForm):
    username = forms.CharField(label='Username', widget=forms.TextInput(attrs={'class': 'form-input'}))
    password = forms.CharField(label='Password', widget=forms.PasswordInput(attrs={'class': 'form-input'}))


class RegisterUserForm(UserCreationForm):
    username = forms.CharField(label='Username', widget=forms.TextInput(attrs={'class': 'form-input'}))
    email = forms.EmailField(label='Email', widget=forms.TextInput(attrs={'class': 'form-input'}))
    first_name = forms.CharField(label='Name', widget=forms.TextInput(attrs={'class': 'form-input'}))
    last_name = forms.CharField(label='Surname', widget=forms.TextInput(attrs={'class': 'form-input'}))
    password1 = forms.CharField(label='Password', widget=forms.PasswordInput(attrs={'class': 'form-input'}))
    password2 = forms.CharField(label='Repeat password', widget=forms.PasswordInput(attrs={'class': 'form-input'}))

    class Meta:
        model = User
        fields = ('username', 'first_name', 'last_name', 'email', 'password1', 'password2')

    def clean_email(self):
        email = self.cleaned_data['email']
        if User.objects.filter(email=email).exists():
            raise ValidationError("email exists")
        return email
